[2025-06-18T22:15:09.283+0000] {taskinstance.py:1956} INFO - Dependencies all met for dep_context=non-requeueable deps ti=<TaskInstance: etl_cassandra_to_clickhouse.load manual__2025-06-18T22:15:02.766299+00:00 [queued]>
[2025-06-18T22:15:09.297+0000] {taskinstance.py:1956} INFO - Dependencies all met for dep_context=requeueable deps ti=<TaskInstance: etl_cassandra_to_clickhouse.load manual__2025-06-18T22:15:02.766299+00:00 [queued]>
[2025-06-18T22:15:09.298+0000] {taskinstance.py:2170} INFO - Starting attempt 1 of 2
[2025-06-18T22:15:09.317+0000] {taskinstance.py:2191} INFO - Executing <Task(PythonOperator): load> on 2025-06-18 22:15:02.766299+00:00
[2025-06-18T22:15:09.324+0000] {standard_task_runner.py:60} INFO - Started process 274 to run task
[2025-06-18T22:15:09.328+0000] {standard_task_runner.py:87} INFO - Running: ['airflow', 'tasks', 'run', 'etl_cassandra_to_clickhouse', 'load', 'manual__2025-06-18T22:15:02.766299+00:00', '--job-id', '73', '--raw', '--subdir', 'DAGS_FOLDER/cassandra_to_clickhouse_dag.py', '--cfg-path', '/tmp/tmp_1t1r0wv']
[2025-06-18T22:15:09.330+0000] {standard_task_runner.py:88} INFO - Job 73: Subtask load
[2025-06-18T22:15:09.404+0000] {task_command.py:423} INFO - Running <TaskInstance: etl_cassandra_to_clickhouse.load manual__2025-06-18T22:15:02.766299+00:00 [running]> on host 31ff11dc1157
[2025-06-18T22:15:09.534+0000] {taskinstance.py:2480} INFO - Exporting env vars: AIRFLOW_CTX_DAG_OWNER='airflow' AIRFLOW_CTX_DAG_ID='etl_cassandra_to_clickhouse' AIRFLOW_CTX_TASK_ID='load' AIRFLOW_CTX_EXECUTION_DATE='2025-06-18T22:15:02.766299+00:00' AIRFLOW_CTX_TRY_NUMBER='1' AIRFLOW_CTX_DAG_RUN_ID='manual__2025-06-18T22:15:02.766299+00:00'
[2025-06-18T22:15:09.584+0000] {base.py:83} INFO - Using connection ID 'clickhouse_conn' for task execution.
[2025-06-18T22:15:09.599+0000] {taskinstance.py:2698} ERROR - Task failed with exception
Traceback (most recent call last):
  File "/home/airflow/.local/lib/python3.8/site-packages/airflow/models/taskinstance.py", line 433, in _execute_task
    result = execute_callable(context=context, **execute_callable_kwargs)
  File "/home/airflow/.local/lib/python3.8/site-packages/airflow/operators/python.py", line 199, in execute
    return_value = self.execute_callable()
  File "/home/airflow/.local/lib/python3.8/site-packages/airflow/operators/python.py", line 216, in execute_callable
    return self.python_callable(*self.op_args, **self.op_kwargs)
  File "/opt/airflow/dags/cassandra_to_clickhouse_dag.py", line 53, in load_into_clickhouse
    client = get_client(host=conn.host, port=8123)
  File "/home/airflow/.local/lib/python3.8/site-packages/clickhouse_connect/driver/__init__.py", line 122, in create_client
    return HttpClient(interface, host, port, username, password, database, access_token,
  File "/home/airflow/.local/lib/python3.8/site-packages/clickhouse_connect/driver/httpclient.py", line 165, in __init__
    super().__init__(database=database,
  File "/home/airflow/.local/lib/python3.8/site-packages/clickhouse_connect/driver/client.py", line 70, in __init__
    self._init_common_settings(apply_server_timezone)
  File "/home/airflow/.local/lib/python3.8/site-packages/clickhouse_connect/driver/client.py", line 75, in _init_common_settings
    tuple(self.command('SELECT version(), timezone()', use_database=False))
  File "/home/airflow/.local/lib/python3.8/site-packages/clickhouse_connect/driver/httpclient.py", line 368, in command
    response = self._raw_request(payload, params, headers, method, fields=fields, server_wait=False)
  File "/home/airflow/.local/lib/python3.8/site-packages/clickhouse_connect/driver/httpclient.py", line 481, in _raw_request
    self._error_handler(response)
  File "/home/airflow/.local/lib/python3.8/site-packages/clickhouse_connect/driver/httpclient.py", line 402, in _error_handler
    raise OperationalError(err_str) if retried else DatabaseError(err_str) from None
clickhouse_connect.driver.exceptions.DatabaseError: HTTPDriver for http://clickhouse:8123 received ClickHouse error code 194
 Code: 194. DB::Exception: default: Authentication failed: ***word is incorrect, or there is no user with such name.

If you use ClickHouse Cloud, the ***word can be reset at https://clickhouse.cloud/
on the settings page for the corresponding service.

If you have installed ClickHouse and forgot ***word you can reset it in the configuration file.
The ***word for default user is typically located at /etc/clickhouse-server/users.d/default-***word.xml
and deleting this file will reset the ***word.
See also /etc/clickhouse-server/users.xml on the server where ClickHouse is installed.

. (REQUIRED_PASSWORD) (version 25.5.2.47 (official build))

[2025-06-18T22:15:09.620+0000] {taskinstance.py:1138} INFO - Marking task as UP_FOR_RETRY. dag_id=etl_cassandra_to_clickhouse, task_id=load, execution_date=20250618T221502, start_date=20250618T221509, end_date=20250618T221509
[2025-06-18T22:15:09.639+0000] {standard_task_runner.py:107} ERROR - Failed to execute job 73 for task load (HTTPDriver for http://clickhouse:8123 received ClickHouse error code 194
 Code: 194. DB::Exception: default: Authentication failed: ***word is incorrect, or there is no user with such name.

If you use ClickHouse Cloud, the ***word can be reset at https://clickhouse.cloud/
on the settings page for the corresponding service.

If you have installed ClickHouse and forgot ***word you can reset it in the configuration file.
The ***word for default user is typically located at /etc/clickhouse-server/users.d/default-***word.xml
and deleting this file will reset the ***word.
See also /etc/clickhouse-server/users.xml on the server where ClickHouse is installed.

. (REQUIRED_PASSWORD) (version 25.5.2.47 (official build))
; 274)
[2025-06-18T22:15:09.661+0000] {local_task_job_runner.py:234} INFO - Task exited with return code 1
[2025-06-18T22:15:09.706+0000] {taskinstance.py:3280} INFO - 0 downstream tasks scheduled from follow-on schedule check
